Workbook

Sheet Summary
A1: MFP Refund Reconciliation — Unit Economics Summary
A2: Reconciliation + recovery for independent pharmacies (no refund advances). Change the scenario on Assumptions!E4.
A4: Scenario | C4: =CHOOSE(Assumptions!$E$4,"Low","Base","High") -> Base
A6: Metric | B6: Unit | C6: 2027 | D6: 2028 | E6: 2029 | F6: 2030 | G6: 2031
A7: Ending stores | B7: stores | C7: =Model!C6 -> 300 | D7: =Model!D6 -> 1000 | E7: =Model!E6 -> 2000 | F7: =Model!F6 -> 3000 | G7: =Model!G6 -> 3500
A8: Ending Part B clinics | B8: clinics | C8: =Model!C10 -> 0 | D8: =Model!D10 -> 25 | E8: =Model!E10 -> 100 | F8: =Model!F10 -> 250 | G8: =Model!G10 -> 400
A9: Net revenue | B9: $ | C9: =Model!C30 -> 980496 | D9: =Model!D30 -> 4333951.2 | E9: =Model!E30 -> 10150802 | F9: =Model!F30 -> 17227256 | G9: =Model!G30 -> 22392511
A10: Gross margin | B10: % | C10: =Model!C41 -> 0.76848452 | D10: =Model!D41 -> 0.86455777 | E10: =Model!E41 -> 0.89606733 | F10: =Model!F41 -> 0.91525058 | G10: =Model!G41 -> 0.92542149
A11: EBITDA | B11: $ | C11: =Model!C54 -> 43496 | D11: =Model!D54 -> 2356951.2 | E11: =Model!E54 -> 7110802.4 | F11: =Model!F54 -> 13447256 | G11: =Model!G54 -> 18127511
A12: EBITDA margin | B12: % | C12: =Model!C55 -> 0.044361221 | D12: =Model!D55 -> 0.54383427 | E12: =Model!E55 -> 0.70051629 | F12: =Model!F55 -> 0.78058026 | G12: =Model!G55 -> 0.80953453
A13: Cumulative cash from operations | B13: $ | C13: =Model!C56 -> 43496 | D13: =Model!D56 -> 2400447.2 | E13: =Model!E56 -> 9511249.6 | F13: =Model!F56 -> 22958506 | G13: =Model!G56 -> 41086016
A14: Our revenue per store | B14: $ / store / yr | C14: =Model!C20 -> 7428 | D14: =Model!D20 -> 7314.6 | E14: =Model!E20 -> 7121.82 | F14: =Model!F20 -> 6876.0255 | G14: =Model!G20 -> 6465.9128
A15: Recovered for each pharmacy | B15: $ / store / yr | C15: =Model!C17 -> 20160 | D15: =Model!D17 -> 19706.4 | E15: =Model!E17 -> 18935.28 | F15: =Model!F17 -> 17952.102 | G15: =Model!G17 -> 16311.651
A16: Pharmacy return on fees paid | B16: x | C16: =Model!C22 -> 2.7140549 | D16: =Model!D22 -> 2.6941186 | E16: =Model!E22 -> 2.6587698 | F16: =Model!F22 -> 2.6108254 | G16: =Model!G22 -> 2.5227144
A17: Total recovered for pharmacies | B17: $ | C17: =Model!C59 -> 3024000 | D17: =Model!D59 -> 12809160 | E17: =Model!E59 -> 28402920 | F17: =Model!F59 -> 44880255 | G17: =Model!G59 -> 53012867
A19: Peak funding need | C19: =Model!C62 -> 0
A20: Enterprise value at exit (2031) | C20: =Model!C63 -> 78373787
A21: Founder equity value at exit | C21: =Model!C64 -> 47024272
A23: How to use
A24: 1. Set the scenario on Assumptions!E4 (1 = Low, 2 = Base, 3 = High).
A25: 2. Edit blue cells on Assumptions and Ramp. Yellow cells are the biggest levers.
A26: 3. Replace the leakage rate and Rx volume with pilot data as soon as you have it (Oswald's, NCPA interviews).
A27: 4. Sensitivity tab shows 2029 results across leakage rate × subscription price.

Sheet Assumptions
A1: MFP Refund Reconciliation — Key Assumptions
A2: Reconciliation-only model (no refund advances). Blue = input; yellow = key lever; black = formula.
A4: Scenario selector | E4: 2 | F4: 1 = Low, 2 = Base, 3 = High
A6: Input | B6: Low | C6: Base | D6: High | E6: Selected | F6: Unit | G6: Notes / source
A7: Refund volume (per store, 2026 drug list)
A8: Negotiated-drug (MFP) prescriptions per store per month | B8: 50 | C8: 80 | D8: 110 | E8: =CHOOSE(Assumptions!$E$4,B8,C8,D8) -> 80 | F8: Rx / month | G8: Estimate: ~1,000–1,200 Rx/wk store, ~35–45% Part D, MFP drugs a few % of Part D fills. Validate with pilot data.
A9: Average refund per MFP prescription | B9: 300 | C9: 375 | D9: 450 | E9: =CHOOSE(Assumptions!$E$4,B9,C9,D9) -> 375 | F9: $ / Rx | G9: WAC minus MFP. Eliquis 60 tabs ≈ $606 WAC − $231 MFP ≈ $375 (approx.).
A10: Recovery revenue
A11: Recoverable leakage, year 1 (% of refunds missing / wrong) | B11: 0.02 | C11: 0.04 | D11: 0.07 | E11: =CHOOSE(Assumptions!$E$4,B11,C11,D11) -> 0.04 | F11: % of refunds | G11: Plenful reports up to 20% missing for health systems (Apr 2026). We assume far less. #1 thing to validate.
A12: Annual decline in leakage rate (system matures) | B12: 0.25 | C12: 0.15 | D12: 0.1 | E12: =CHOOSE(Assumptions!$E$4,B12,C12,D12) -> 0.15 | F12: % / yr | G12: Assumes CMS/manufacturers fix errors over time. Low case = faster fix.
A13: Share of identified leakage actually recovered | B13: 0.6 | C13: 0.7 | D13: 0.8 | E13: =CHOOSE(Assumptions!$E$4,B13,C13,D13) -> 0.7 | F13: % | G13: Good-faith inquiries + MTF complaints; some claims unrecoverable.
A14: Contingency fee on recovered dollars | B14: 0.2 | C14: 0.25 | D14: 0.3 | E14: =CHOOSE(Assumptions!$E$4,B14,C14,D14) -> 0.25 | F14: % of recovered | G14: Typical recovery/contingency pricing range.
A15: Subscription & channel
A16: Monitoring subscription per store | B16: 149 | C16: 199 | D16: 249 | E16: =CHOOSE(Assumptions!$E$4,B16,C16,D16) -> 199 | F16: $ / month | G16: Claim-level reconciliation, aging, alerts, enrollment upkeep.
A17: Share of stores sourced through co-op channel (IPC etc.) | B17: 0.7 | C17: 0.6 | D17: 0.5 | E17: =CHOOSE(Assumptions!$E$4,B17,C17,D17) -> 0.6 | F17: % of stores | G17: Channel-heavy go-to-market.
A18: Co-op revenue share on channel stores | B18: 0.25 | C18: 0.2 | D18: 0.15 | E18: =CHOOSE(Assumptions!$E$4,B18,C18,D18) -> 0.2 | F18: % of store revenue | G18: Paid to co-op partner on subscription + recovery revenue.
A19: Part B clinic revenue (from 2028) | B19: 8000 | C19: 12000 | D19: 18000 | E19: =CHOOSE(Assumptions!$E$4,B19,C19,D19) -> 12000 | F19: $ / clinic / yr | G19: Part B drugs enter negotiation in 2028; clinics have larger refunds per claim. Effectuation details still being set by CMS.
A20: Cost of revenue
A21: Onboarding cost per new store | B21: 400 | C21: 300 | D21: 200 | E21: =CHOOSE(Assumptions!$E$4,B21,C21,D21) -> 300 | F21: $ / new store | G21: Data authorizations, PMS export setup, enrollment clean-up (staff hours).
A22: Data, hosting & tooling per store | B22: 20 | C22: 15 | D22: 10 | E22: =CHOOSE(Assumptions!$E$4,B22,C22,D22) -> 15 | F22: $ / store / month | G22: Cloud, storage, SFTP, monitoring.
A23: Drug pricing database license (WAC) | B23: 50000 | C23: 35000 | D23: 25000 | E23: =CHOOSE(Assumptions!$E$4,B23,C23,D23) -> 35000 | F23: $ / yr | G23: Medi-Span / First Databank. Placeholder — get a quote.
A24: Stores supported per recovery / support analyst | B24: 200 | C24: 300 | D24: 400 | E24: =CHOOSE(Assumptions!$E$4,B24,C24,D24) -> 300 | F24: stores / FTE | G24: Exceptions, disputes, customer support.
A25: Loaded cost per analyst | B25: 80000 | C25: 75000 | D25: 70000 | E25: =CHOOSE(Assumptions!$E$4,B25,C25,D25) -> 75000 | F25: $ / yr | G25: Salary + benefits + taxes.
A26: Operating costs
A27: Founder salary | B27: 120000 | C27: 120000 | D27: 120000 | E27: =CHOOSE(Assumptions!$E$4,B27,C27,D27) -> 120000 | F27: $ / yr | G27: Your draw; edit freely.
A28: Loaded cost per engineer | B28: 190000 | C28: 180000 | D28: 170000 | E28: =CHOOSE(Assumptions!$E$4,B28,C28,D28) -> 180000 | F28: $ / yr | G28: Headcount on Ramp tab.
A29: Loaded cost per channel / sales manager | B29: 150000 | C29: 140000 | D29: 130000 | E29: =CHOOSE(Assumptions!$E$4,B29,C29,D29) -> 140000 | F29: $ / yr | G29: Headcount on Ramp tab.
A30: Acquisition cost per new direct (non-channel) store | B30: 1500 | C30: 1000 | D30: 600 | E30: =CHOOSE(Assumptions!$E$4,B30,C30,D30) -> 1000 | F30: $ / new store | G30: Travel, conferences, demos, free audits.
A31: Exit
A32: Exit multiple on final-year net revenue | B32: 2 | C32: 3.5 | D32: 5 | E32: =CHOOSE(Assumptions!$E$4,B32,C32,D32) -> 3.5 | F32: x revenue | G32: Vertical SaaS / tech-enabled services range. Illustrative only.
A33: Founder ownership at exit | B33: 0.5 | C33: 0.6 | D33: 0.7 | E33: =CHOOSE(Assumptions!$E$4,B33,C33,D33) -> 0.6 | F33: % | G33: After advisor/co-founder equity and any raise.

Sheet Ramp
A1: Ramp Inputs by Year
A2: Per-year inputs. Scenario rows feed the 'Selected' row via the selector on Assumptions.
A4: Input | B4: Unit | C4: 2027 | D4: 2028 | E4: 2029 | F4: 2030 | G4: 2031 | H4: Notes
A5: Refund volume growth
A6: Refund volume vs. 2026 drug list | B6: x 2026 | C6: 2 | D6: 2.3 | E6: 2.6 | F6: 2.9 | G6: 3.1 | H6: 2027 adds 15 drugs incl. Ozempic/Wegovy; later rounds add more. Assumption — refine with pilot data.
A8: Stores under contract (end of year)
A9: Ending stores — Low | B9: stores | C9: 150 | D9: 400 | E9: 800 | F9: 1200 | G9: 1500
A10: Ending stores — Base | B10: stores | C10: 300 | D10: 1000 | E10: 2000 | F10: 3000 | G10: 3500 | H10: ~19,000 independents in the US.
A11: Ending stores — High | B11: stores | C11: 500 | D11: 1800 | E11: 3500 | F11: 5000 | G11: 6000
A12: Ending stores — Selected | B12: stores | C12: =CHOOSE(Assumptions!$E$4,C9,C10,C11) -> 300 | D12: =CHOOSE(Assumptions!$E$4,D9,D10,D11) -> 1000 | E12: =CHOOSE(Assumptions!$E$4,E9,E10,E11) -> 2000 | F12: =CHOOSE(Assumptions!$E$4,F9,F10,F11) -> 3000 | G12: =CHOOSE(Assumptions!$E$4,G9,G10,G11) -> 3500
A14: Part B clinics under contract (end of year)
A15: Ending clinics — Low | B15: clinics | C15: 0 | D15: 10 | E15: 40 | F15: 100 | G15: 150
A16: Ending clinics — Base | B16: clinics | C16: 0 | D16: 25 | E16: 100 | F16: 250 | G16: 400 | H16: Part B drugs enter the program in 2028.
A17: Ending clinics — High | B17: clinics | C17: 0 | D17: 50 | E17: 200 | F17: 450 | G17: 700
A18: Ending clinics — Selected | B18: clinics | C18: =CHOOSE(Assumptions!$E$4,C15,C16,C17) -> 0 | D18: =CHOOSE(Assumptions!$E$4,D15,D16,D17) -> 25 | E18: =CHOOSE(Assumptions!$E$4,E15,E16,E17) -> 100 | F18: =CHOOSE(Assumptions!$E$4,F15,F16,F17) -> 250 | G18: =CHOOSE(Assumptions!$E$4,G15,G16,G17) -> 400
A20: Team & fixed costs
A21: Engineers (excluding founder) | B21: FTE | C21: 1 | D21: 2 | E21: 3 | F21: 4 | G21: 5 | H21: You build v1 yourself.
A22: Channel / sales managers | B22: FTE | C22: 0.5 | D22: 1 | E22: 2 | F22: 2 | G22: 3
A23: Pharmacist lead / advisor cost | B23: $ / yr | C23: 60000 | D23: 170000 | E23: 170000 | F23: 175000 | G23: 180000 | H23: 2027 = part-time advisor; full-time head of pharmacy ops from 2028.
A24: Legal, compliance & security (HIPAA, SOC 2) | B24: $ / yr | C24: 75000 | D24: 120000 | E24: 150000 | F24: 175000 | G24: 200000 | H24: Handling PHI: BAAs, audits, insurance.
A25: Marketing & conferences | B25: $ / yr | C25: 25000 | D25: 50000 | E25: 75000 | F25: 100000 | G25: 125000 | H25: NCPA, state associations, co-op events.
A26: G&A (accounting, insurance, tools, office, travel) | B26: $ / yr | C26: 60000 | D26: 150000 | E26: 250000 | F26: 350000 | G26: 450000 | H26: General overhead as the team grows.

Sheet Model
A1: Five-Year Model — Reconciliation Only
A2: All figures in US$ unless noted. Green = link to another tab; black = calculation.
A4: Line item | B4: Unit | C4: 2027 | D4: 2028 | E4: 2029 | F4: 2030 | G4: 2031
A5: Customers
A6: Ending stores | B6: stores | C6: =Ramp!C12 -> 300 | D6: =Ramp!D12 -> 1000 | E6: =Ramp!E12 -> 2000 | F6: =Ramp!F12 -> 3000 | G6: =Ramp!G12 -> 3500
A7: Beginning stores | B7: stores | C7: =0 -> 0 | D7: =C6 -> 300 | E7: =D6 -> 1000 | F7: =E6 -> 2000 | G7: =F6 -> 3000
A8: New stores added (net) | B8: stores | C8: =MAX(C6-C7,0) -> 300 | D8: =MAX(D6-D7,0) -> 700 | E8: =MAX(E6-E7,0) -> 1000 | F8: =MAX(F6-F7,0) -> 1000 | G8: =MAX(G6-G7,0) -> 500
A9: Average stores | B9: stores | C9: =(C7+C6)/2 -> 150 | D9: =(D7+D6)/2 -> 650 | E9: =(E7+E6)/2 -> 1500 | F9: =(F7+F6)/2 -> 2500 | G9: =(G7+G6)/2 -> 3250
A10: Ending Part B clinics | B10: clinics | C10: =Ramp!C18 -> 0 | D10: =Ramp!D18 -> 25 | E10: =Ramp!E18 -> 100 | F10: =Ramp!F18 -> 250 | G10: =Ramp!G18 -> 400
A11: Average Part B clinics | B11: clinics | C11: =(C10)/2 -> 0 | D11: =(C10+D10)/2 -> 12.5 | E11: =(D10+E10)/2 -> 62.5 | F11: =(E10+F10)/2 -> 175 | G11: =(F10+G10)/2 -> 325
A13: Per-store economics
A14: MFP refunds flowing to store | B14: $ / store / yr | C14: =Assumptions!$E$8*Assumptions!$E$9*12*Ramp!C6 -> 720000 | D14: =Assumptions!$E$8*Assumptions!$E$9*12*Ramp!D6 -> 828000 | E14: =Assumptions!$E$8*Assumptions!$E$9*12*Ramp!E6 -> 936000 | F14: =Assumptions!$E$8*Assumptions!$E$9*12*Ramp!F6 -> 1044000 | G14: =Assumptions!$E$8*Assumptions!$E$9*12*Ramp!G6 -> 1116000
A15: Recoverable leakage rate | B15: % | C15: =Assumptions!$E$11*(1-Assumptions!$E$12)^0 -> 0.04 | D15: =Assumptions!$E$11*(1-Assumptions!$E$12)^1 -> 0.034 | E15: =Assumptions!$E$11*(1-Assumptions!$E$12)^2 -> 0.0289 | F15: =Assumptions!$E$11*(1-Assumptions!$E$12)^3 -> 0.024565 | G15: =Assumptions!$E$11*(1-Assumptions!$E$12)^4 -> 0.02088025
A16: Leakage identified | B16: $ / store / yr | C16: =C14*C15 -> 28800 | D16: =D14*D15 -> 28152 | E16: =E14*E15 -> 27050.4 | F16: =F14*F15 -> 25645.86 | G16: =G14*G15 -> 23302.359
A17: Leakage recovered for store | B17: $ / store / yr | C17: =C16*Assumptions!$E$13 -> 20160 | D17: =D16*Assumptions!$E$13 -> 19706.4 | E17: =E16*Assumptions!$E$13 -> 18935.28 | F17: =F16*Assumptions!$E$13 -> 17952.102 | G17: =G16*Assumptions!$E$13 -> 16311.651
A18: Our contingency revenue | B18: $ / store / yr | C18: =C17*Assumptions!$E$14 -> 5040 | D18: =D17*Assumptions!$E$14 -> 4926.6 | E18: =E17*Assumptions!$E$14 -> 4733.82 | F18: =F17*Assumptions!$E$14 -> 4488.0255 | G18: =G17*Assumptions!$E$14 -> 4077.9128
A19: Our subscription revenue | B19: $ / store / yr | C19: =Assumptions!$E$16*12 -> 2388 | D19: =Assumptions!$E$16*12 -> 2388 | E19: =Assumptions!$E$16*12 -> 2388 | F19: =Assumptions!$E$16*12 -> 2388 | G19: =Assumptions!$E$16*12 -> 2388
A20: Our gross revenue per store | B20: $ / store / yr | C20: =C18+C19 -> 7428 | D20: =D18+D19 -> 7314.6 | E20: =E18+E19 -> 7121.82 | F20: =F18+F19 -> 6876.0255 | G20: =G18+G19 -> 6465.9128
A21: Net gain to pharmacy (recovered − our fees) | B21: $ / store / yr | C21: =C17-C20 -> 12732 | D21: =D17-D20 -> 12391.8 | E21: =E17-E20 -> 11813.46 | F21: =F17-F20 -> 11076.076 | G21: =G17-G20 -> 9845.7385
A22: Pharmacy return on fees paid | B22: x | C22: =IFERROR(C17/C20,0) -> 2.7140549 | D22: =IFERROR(D17/D20,0) -> 2.6941186 | E22: =IFERROR(E17/E20,0) -> 2.6587698 | F22: =IFERROR(F17/F20,0) -> 2.6108254 | G22: =IFERROR(G17/G20,0) -> 2.5227144
A24: Revenue
A25: Subscription revenue | B25: $ | C25: =C9*C19 -> 358200 | D25: =D9*D19 -> 1552200 | E25: =E9*E19 -> 3582000 | F25: =F9*F19 -> 5970000 | G25: =G9*G19 -> 7761000
A26: Recovery (contingency) revenue | B26: $ | C26: =C9*C18 -> 756000 | D26: =D9*D18 -> 3202290 | E26: =E9*E18 -> 7100730 | F26: =F9*F18 -> 11220064 | G26: =G9*G18 -> 13253217
A27: Part B clinic revenue | B27: $ | C27: =C11*Assumptions!$E$19 -> 0 | D27: =D11*Assumptions!$E$19 -> 150000 | E27: =E11*Assumptions!$E$19 -> 750000 | F27: =F11*Assumptions!$E$19 -> 2100000 | G27: =G11*Assumptions!$E$19 -> 3900000
A28: Gross revenue | B28: $ | C28: =SUM(C25:C27) -> 1114200 | D28: =SUM(D25:D27) -> 4904490 | E28: =SUM(E25:E27) -> 11432730 | F28: =SUM(F25:F27) -> 19290064 | G28: =SUM(G25:G27) -> 24914217
A29: Less: co-op revenue share | B29: $ | C29: =-(C25+C26)*Assumptions!$E$17*Assumptions!$E$18 -> -133704 | D29: =-(D25+D26)*Assumptions!$E$17*Assumptions!$E$18 -> -570538.8 | E29: =-(E25+E26)*Assumptions!$E$17*Assumptions!$E$18 -> -1281927.6 | F29: =-(F25+F26)*Assumptions!$E$17*Assumptions!$E$18 -> -2062807.6 | G29: =-(G25+G26)*Assumptions!$E$17*Assumptions!$E$18 -> -2521706
A30: Net revenue | B30: $ | C30: =C28+C29 -> 980496 | D30: =D28+D29 -> 4333951.2 | E30: =E28+E29 -> 10150802 | F30: =F28+F29 -> 17227256 | G30: =G28+G29 -> 22392511
A31: Net revenue growth | B31: % | C31: ="" | D31: =IFERROR(D30/C30-1,0) -> 3.420162 | E31: =IFERROR(E30/D30-1,0) -> 1.3421589 | F31: =IFERROR(F30/E30-1,0) -> 0.69713245 | G31: =IFERROR(G30/F30-1,0) -> 0.29983037
A33: Cost of revenue
A34: Data, hosting & tooling | B34: $ | C34: =C9*Assumptions!$E$22*12 -> 27000 | D34: =D9*Assumptions!$E$22*12 -> 117000 | E34: =E9*Assumptions!$E$22*12 -> 270000 | F34: =F9*Assumptions!$E$22*12 -> 450000 | G34: =G9*Assumptions!$E$22*12 -> 585000
A35: Drug pricing database license | B35: $ | C35: =Assumptions!$E$23 -> 35000 | D35: =Assumptions!$E$23 -> 35000 | E35: =Assumptions!$E$23 -> 35000 | F35: =Assumptions!$E$23 -> 35000 | G35: =Assumptions!$E$23 -> 35000
A36: Onboarding | B36: $ | C36: =C8*Assumptions!$E$21 -> 90000 | D36: =D8*Assumptions!$E$21 -> 210000 | E36: =E8*Assumptions!$E$21 -> 300000 | F36: =F8*Assumptions!$E$21 -> 300000 | G36: =G8*Assumptions!$E$21 -> 150000
A37: Recovery / support analysts | B37: FTE | C37: =ROUNDUP((C9+C11)/Assumptions!$E$24,0) -> 1 | D37: =ROUNDUP((D9+D11)/Assumptions!$E$24,0) -> 3 | E37: =ROUNDUP((E9+E11)/Assumptions!$E$24,0) -> 6 | F37: =ROUNDUP((F9+F11)/Assumptions!$E$24,0) -> 9 | G37: =ROUNDUP((G9+G11)/Assumptions!$E$24,0) -> 12
A38: Analyst cost | B38: $ | C38: =C37*Assumptions!$E$25 -> 75000 | D38: =D37*Assumptions!$E$25 -> 225000 | E38: =E37*Assumptions!$E$25 -> 450000 | F38: =F37*Assumptions!$E$25 -> 675000 | G38: =G37*Assumptions!$E$25 -> 900000
A39: Total cost of revenue | B39: $ | C39: =C34+C35+C36+C38 -> 227000 | D39: =D34+D35+D36+D38 -> 587000 | E39: =E34+E35+E36+E38 -> 1055000 | F39: =F34+F35+F36+F38 -> 1460000 | G39: =G34+G35+G36+G38 -> 1670000
A40: Gross profit | B40: $ | C40: =C30-C39 -> 753496 | D40: =D30-D39 -> 3746951.2 | E40: =E30-E39 -> 9095802.4 | F40: =F30-F39 -> 15767256 | G40: =G30-G39 -> 20722511
A41: Gross margin | B41: % | C41: =IFERROR(C40/C30,0) -> 0.76848452 | D41: =IFERROR(D40/D30,0) -> 0.86455777 | E41: =IFERROR(E40/E30,0) -> 0.89606733 | F41: =IFERROR(F40/F30,0) -> 0.91525058 | G41: =IFERROR(G40/G30,0) -> 0.92542149
A43: Operating expenses
A44: Founder salary | B44: $ | C44: =Assumptions!$E$27 -> 120000 | D44: =Assumptions!$E$27 -> 120000 | E44: =Assumptions!$E$27 -> 120000 | F44: =Assumptions!$E$27 -> 120000 | G44: =Assumptions!$E$27 -> 120000
A45: Engineering | B45: $ | C45: =Ramp!C21*Assumptions!$E$28 -> 180000 | D45: =Ramp!D21*Assumptions!$E$28 -> 360000 | E45: =Ramp!E21*Assumptions!$E$28 -> 540000 | F45: =Ramp!F21*Assumptions!$E$28 -> 720000 | G45: =Ramp!G21*Assumptions!$E$28 -> 900000
...

Sheet Sensitivity
A1: Sensitivity — 2029 (Year 3)
A2: How net revenue and EBITDA move with the two biggest unknowns. Other inputs stay at the selected scenario.
A4: 2029 net revenue ($)
A5: Year-1 leakage rate ↓ / subscription $/mo → | B5: 99 | C5: 149 | D5: 199 | E5: 249 | F5: 299
A6: 0.01 | B6: =Model!$E$9*(B$5*12+Model!$E$14*$A6*(1-Assumptions!$E$12)^2*Assumptions!$E$13*Assumptions!$E$14)*(1-Assumptions!$E$17*Assumptions!$E$18)+Model!$E$27 -> 3880320.6 | C6: =Model!$E$9*(C$5*12+Model!$E$14*$A6*(1-Assumptions!$E$12)^2*Assumptions!$E$13*Assumptions!$E$14)*(1-Assumptions!$E$17*Assumptions!$E$18)+Model!$E$27 -> 4672320.6 | D6: =Model!$E$9*(D$5*12+Model!$E$14*$A6*(1-Assumptions!$E$12)^2*Assumptions!$E$13*Assumptions!$E$14)*(1-Assumptions!$E$17*Assumptions!$E$18)+Model!$E$27 -> 5464320.6 | E6: =Model!$E$9*(E$5*12+Model!$E$14*$A6*(1-Assumptions!$E$12)^2*Assumptions!$E$13*Assumptions!$E$14)*(1-Assumptions!$E$17*Assumptions!$E$18)+Model!$E$27 -> 6256320.6 | F6: =Model!$E$9*(F$5*12+Model!$E$14*$A6*(1-Assumptions!$E$12)^2*Assumptions!$E$13*Assumptions!$E$14)*(1-Assumptions!$E$17*Assumptions!$E$18)+Model!$E$27 -> 7048320.6
A7: 0.02 | B7: =Model!$E$9*(B$5*12+Model!$E$14*$A7*(1-Assumptions!$E$12)^2*Assumptions!$E$13*Assumptions!$E$14)*(1-Assumptions!$E$17*Assumptions!$E$18)+Model!$E$27 -> 5442481.2 | C7: =Model!$E$9*(C$5*12+Model!$E$14*$A7*(1-Assumptions!$E$12)^2*Assumptions!$E$13*Assumptions!$E$14)*(1-Assumptions!$E$17*Assumptions!$E$18)+Model!$E$27 -> 6234481.2 | D7: =Model!$E$9*(D$5*12+Model!$E$14*$A7*(1-Assumptions!$E$12)^2*Assumptions!$E$13*Assumptions!$E$14)*(1-Assumptions!$E$17*Assumptions!$E$18)+Model!$E$27 -> 7026481.2 | E7: =Model!$E$9*(E$5*12+Model!$E$14*$A7*(1-Assumptions!$E$12)^2*Assumptions!$E$13*Assumptions!$E$14)*(1-Assumptions!$E$17*Assumptions!$E$18)+Model!$E$27 -> 7818481.2 | F7: =Model!$E$9*(F$5*12+Model!$E$14*$A7*(1-Assumptions!$E$12)^2*Assumptions!$E$13*Assumptions!$E$14)*(1-Assumptions!$E$17*Assumptions!$E$18)+Model!$E$27 -> 8610481.2
A8: 0.03 | B8: =Model!$E$9*(B$5*12+Model!$E$14*$A8*(1-Assumptions!$E$12)^2*Assumptions!$E$13*Assumptions!$E$14)*(1-Assumptions!$E$17*Assumptions!$E$18)+Model!$E$27 -> 7004641.8 | C8: =Model!$E$9*(C$5*12+Model!$E$14*$A8*(1-Assumptions!$E$12)^2*Assumptions!$E$13*Assumptions!$E$14)*(1-Assumptions!$E$17*Assumptions!$E$18)+Model!$E$27 -> 7796641.8 | D8: =Model!$E$9*(D$5*12+Model!$E$14*$A8*(1-Assumptions!$E$12)^2*Assumptions!$E$13*Assumptions!$E$14)*(1-Assumptions!$E$17*Assumptions!$E$18)+Model!$E$27 -> 8588641.8 | E8: =Model!$E$9*(E$5*12+Model!$E$14*$A8*(1-Assumptions!$E$12)^2*Assumptions!$E$13*Assumptions!$E$14)*(1-Assumptions!$E$17*Assumptions!$E$18)+Model!$E$27 -> 9380641.8 | F8: =Model!$E$9*(F$5*12+Model!$E$14*$A8*(1-Assumptions!$E$12)^2*Assumptions!$E$13*Assumptions!$E$14)*(1-Assumptions!$E$17*Assumptions!$E$18)+Model!$E$27 -> 10172642
A9: 0.04 | B9: =Model!$E$9*(B$5*12+Model!$E$14*$A9*(1-Assumptions!$E$12)^2*Assumptions!$E$13*Assumptions!$E$14)*(1-Assumptions!$E$17*Assumptions!$E$18)+Model!$E$27 -> 8566802.4 | C9: =Model!$E$9*(C$5*12+Model!$E$14*$A9*(1-Assumptions!$E$12)^2*Assumptions!$E$13*Assumptions!$E$14)*(1-Assumptions!$E$17*Assumptions!$E$18)+Model!$E$27 -> 9358802.4 | D9: =Model!$E$9*(D$5*12+Model!$E$14*$A9*(1-Assumptions!$E$12)^2*Assumptions!$E$13*Assumptions!$E$14)*(1-Assumptions!$E$17*Assumptions!$E$18)+Model!$E$27 -> 10150802 | E9: =Model!$E$9*(E$5*12+Model!$E$14*$A9*(1-Assumptions!$E$12)^2*Assumptions!$E$13*Assumptions!$E$14)*(1-Assumptions!$E$17*Assumptions!$E$18)+Model!$E$27 -> 10942802 | F9: =Model!$E$9*(F$5*12+Model!$E$14*$A9*(1-Assumptions!$E$12)^2*Assumptions!$E$13*Assumptions!$E$14)*(1-Assumptions!$E$17*Assumptions!$E$18)+Model!$E$27 -> 11734802
A10: 0.06 | B10: =Model!$E$9*(B$5*12+Model!$E$14*$A10*(1-Assumptions!$E$12)^2*Assumptions!$E$13*Assumptions!$E$14)*(1-Assumptions!$E$17*Assumptions!$E$18)+Model!$E$27 -> 11691124 | C10: =Model!$E$9*(C$5*12+Model!$E$14*$A10*(1-Assumptions!$E$12)^2*Assumptions!$E$13*Assumptions!$E$14)*(1-Assumptions!$E$17*Assumptions!$E$18)+Model!$E$27 -> 12483124 | D10: =Model!$E$9*(D$5*12+Model!$E$14*$A10*(1-Assumptions!$E$12)^2*Assumptions!$E$13*Assumptions!$E$14)*(1-Assumptions!$E$17*Assumptions!$E$18)+Model!$E$27 -> 13275124 | E10: =Model!$E$9*(E$5*12+Model!$E$14*$A10*(1-Assumptions!$E$12)^2*Assumptions!$E$13*Assumptions!$E$14)*(1-Assumptions!$E$17*Assumptions!$E$18)+Model!$E$27 -> 14067124 | F10: =Model!$E$9*(F$5*12+Model!$E$14*$A10*(1-Assumptions!$E$12)^2*Assumptions!$E$13*Assumptions!$E$14)*(1-Assumptions!$E$17*Assumptions!$E$18)+Model!$E$27 -> 14859124
A11: 0.08 | B11: =Model!$E$9*(B$5*12+Model!$E$14*$A11*(1-Assumptions!$E$12)^2*Assumptions!$E$13*Assumptions!$E$14)*(1-Assumptions!$E$17*Assumptions!$E$18)+Model!$E$27 -> 14815445 | C11: =Model!$E$9*(C$5*12+Model!$E$14*$A11*(1-Assumptions!$E$12)^2*Assumptions!$E$13*Assumptions!$E$14)*(1-Assumptions!$E$17*Assumptions!$E$18)+Model!$E$27 -> 15607445 | D11: =Model!$E$9*(D$5*12+Model!$E$14*$A11*(1-Assumptions!$E$12)^2*Assumptions!$E$13*Assumptions!$E$14)*(1-Assumptions!$E$17*Assumptions!$E$18)+Model!$E$27 -> 16399445 | E11: =Model!$E$9*(E$5*12+Model!$E$14*$A11*(1-Assumptions!$E$12)^2*Assumptions!$E$13*Assumptions!$E$14)*(1-Assumptions!$E$17*Assumptions!$E$18)+Model!$E$27 -> 17191445 | F11: =Model!$E$9*(F$5*12+Model!$E$14*$A11*(1-Assumptions!$E$12)^2*Assumptions!$E$13*Assumptions!$E$14)*(1-Assumptions!$E$17*Assumptions!$E$18)+Model!$E$27 -> 17983445
A12: 0.1 | B12: =Model!$E$9*(B$5*12+Model!$E$14*$A12*(1-Assumptions!$E$12)^2*Assumptions!$E$13*Assumptions!$E$14)*(1-Assumptions!$E$17*Assumptions!$E$18)+Model!$E$27 -> 17939766 | C12: =Model!$E$9*(C$5*12+Model!$E$14*$A12*(1-Assumptions!$E$12)^2*Assumptions!$E$13*Assumptions!$E$14)*(1-Assumptions!$E$17*Assumptions!$E$18)+Model!$E$27 -> 18731766 | D12: =Model!$E$9*(D$5*12+Model!$E$14*$A12*(1-Assumptions!$E$12)^2*Assumptions!$E$13*Assumptions!$E$14)*(1-Assumptions!$E$17*Assumptions!$E$18)+Model!$E$27 -> 19523766 | E12: =Model!$E$9*(E$5*12+Model!$E$14*$A12*(1-Assumptions!$E$12)^2*Assumptions!$E$13*Assumptions!$E$14)*(1-Assumptions!$E$17*Assumptions!$E$18)+Model!$E$27 -> 20315766 | F12: =Model!$E$9*(F$5*12+Model!$E$14*$A12*(1-Assumptions!$E$12)^2*Assumptions!$E$13*Assumptions!$E$14)*(1-Assumptions!$E$17*Assumptions!$E$18)+Model!$E$27 -> 21107766
A15: 2029 EBITDA ($)
A16: Year-1 leakage rate ↓ / subscription $/mo → | B16: 99 | C16: 149 | D16: 199 | E16: 249 | F16: 299
A17: 0.01 | B17: =Model!$E$9*(B$16*12+Model!$E$14*$A17*(1-Assumptions!$E$12)^2*Assumptions!$E$13*Assumptions!$E$14)*(1-Assumptions!$E$17*Assumptions!$E$18)+Model!$E$27-Model!$E$30+Model!$E$54 -> 840320.6 | C17: =Model!$E$9*(C$16*12+Model!$E$14*$A17*(1-Assumptions!$E$12)^2*Assumptions!$E$13*Assumptions!$E$14)*(1-Assumptions!$E$17*Assumptions!$E$18)+Model!$E$27-Model!$E$30+Model!$E$54 -> 1632320.6 | D17: =Model!$E$9*(D$16*12+Model!$E$14*$A17*(1-Assumptions!$E$12)^2*Assumptions!$E$13*Assumptions!$E$14)*(1-Assumptions!$E$17*Assumptions!$E$18)+Model!$E$27-Model!$E$30+Model!$E$54 -> 2424320.6 | E17: =Model!$E$9*(E$16*12+Model!$E$14*$A17*(1-Assumptions!$E$12)^2*Assumptions!$E$13*Assumptions!$E$14)*(1-Assumptions!$E$17*Assumptions!$E$18)+Model!$E$27-Model!$E$30+Model!$E$54 -> 3216320.6 | F17: =Model!$E$9*(F$16*12+Model!$E$14*$A17*(1-Assumptions!$E$12)^2*Assumptions!$E$13*Assumptions!$E$14)*(1-Assumptions!$E$17*Assumptions!$E$18)+Model!$E$27-Model!$E$30+Model!$E$54 -> 4008320.6
A18: 0.02 | B18: =Model!$E$9*(B$16*12+Model!$E$14*$A18*(1-Assumptions!$E$12)^2*Assumptions!$E$13*Assumptions!$E$14)*(1-Assumptions!$E$17*Assumptions!$E$18)+Model!$E$27-Model!$E$30+Model!$E$54 -> 2402481.2 | C18: =Model!$E$9*(C$16*12+Model!$E$14*$A18*(1-Assumptions!$E$12)^2*Assumptions!$E$13*Assumptions!$E$14)*(1-Assumptions!$E$17*Assumptions!$E$18)+Model!$E$27-Model!$E$30+Model!$E$54 -> 3194481.2 | D18: =Model!$E$9*(D$16*12+Model!$E$14*$A18*(1-Assumptions!$E$12)^2*Assumptions!$E$13*Assumptions!$E$14)*(1-Assumptions!$E$17*Assumptions!$E$18)+Model!$E$27-Model!$E$30+Model!$E$54 -> 3986481.2 | E18: =Model!$E$9*(E$16*12+Model!$E$14*$A18*(1-Assumptions!$E$12)^2*Assumptions!$E$13*Assumptions!$E$14)*(1-Assumptions!$E$17*Assumptions!$E$18)+Model!$E$27-Model!$E$30+Model!$E$54 -> 4778481.2 | F18: =Model!$E$9*(F$16*12+Model!$E$14*$A18*(1-Assumptions!$E$12)^2*Assumptions!$E$13*Assumptions!$E$14)*(1-Assumptions!$E$17*Assumptions!$E$18)+Model!$E$27-Model!$E$30+Model!$E$54 -> 5570481.2
A19: 0.03 | B19: =Model!$E$9*(B$16*12+Model!$E$14*$A19*(1-Assumptions!$E$12)^2*Assumptions!$E$13*Assumptions!$E$14)*(1-Assumptions!$E$17*Assumptions!$E$18)+Model!$E$27-Model!$E$30+Model!$E$54 -> 3964641.8 | C19: =Model!$E$9*(C$16*12+Model!$E$14*$A19*(1-Assumptions!$E$12)^2*Assumptions!$E$13*Assumptions!$E$14)*(1-Assumptions!$E$17*Assumptions!$E$18)+Model!$E$27-Model!$E$30+Model!$E$54 -> 4756641.8 | D19: =Model!$E$9*(D$16*12+Model!$E$14*$A19*(1-Assumptions!$E$12)^2*Assumptions!$E$13*Assumptions!$E$14)*(1-Assumptions!$E$17*Assumptions!$E$18)+Model!$E$27-Model!$E$30+Model!$E$54 -> 5548641.8 | E19: =Model!$E$9*(E$16*12+Model!$E$14*$A19*(1-Assumptions!$E$12)^2*Assumptions!$E$13*Assumptions!$E$14)*(1-Assumptions!$E$17*Assumptions!$E$18)+Model!$E$27-Model!$E$30+Model!$E$54 -> 6340641.8 | F19: =Model!$E$9*(F$16*12+Model!$E$14*$A19*(1-Assumptions!$E$12)^2*Assumptions!$E$13*Assumptions!$E$14)*(1-Assumptions!$E$17*Assumptions!$E$18)+Model!$E$27-Model!$E$30+Model!$E$54 -> 7132641.8
A20: 0.04 | B20: =Model!$E$9*(B$16*12+Model!$E$14*$A20*(1-Assumptions!$E$12)^2*Assumptions!$E$13*Assumptions!$E$14)*(1-Assumptions!$E$17*Assumptions!$E$18)+Model!$E$27-Model!$E$30+Model!$E$54 -> 5526802.4 | C20: =Model!$E$9*(C$16*12+Model!$E$14*$A20*(1-Assumptions!$E$12)^2*Assumptions!$E$13*Assumptions!$E$14)*(1-Assumptions!$E$17*Assumptions!$E$18)+Model!$E$27-Model!$E$30+Model!$E$54 -> 6318802.4 | D20: =Model!$E$9*(D$16*12+Model!$E$14*$A20*(1-Assumptions!$E$12)^2*Assumptions!$E$13*Assumptions!$E$14)*(1-Assumptions!$E$17*Assumptions!$E$18)+Model!$E$27-Model!$E$30+Model!$E$54 -> 7110802.4 | E20: =Model!$E$9*(E$16*12+Model!$E$14*$A20*(1-Assumptions!$E$12)^2*Assumptions!$E$13*Assumptions!$E$14)*(1-Assumptions!$E$17*Assumptions!$E$18)+Model!$E$27-Model!$E$30+Model!$E$54 -> 7902802.4 | F20: =Model!$E$9*(F$16*12+Model!$E$14*$A20*(1-Assumptions!$E$12)^2*Assumptions!$E$13*Assumptions!$E$14)*(1-Assumptions!$E$17*Assumptions!$E$18)+Model!$E$27-Model!$E$30+Model!$E$54 -> 8694802.4
A21: 0.06 | B21: =Model!$E$9*(B$16*12+Model!$E$14*$A21*(1-Assumptions!$E$12)^2*Assumptions!$E$13*Assumptions!$E$14)*(1-Assumptions!$E$17*Assumptions!$E$18)+Model!$E$27-Model!$E$30+Model!$E$54 -> 8651123.6 | C21: =Model!$E$9*(C$16*12+Model!$E$14*$A21*(1-Assumptions!$E$12)^2*Assumptions!$E$13*Assumptions!$E$14)*(1-Assumptions!$E$17*Assumptions!$E$18)+Model!$E$27-Model!$E$30+Model!$E$54 -> 9443123.6 | D21: =Model!$E$9*(D$16*12+Model!$E$14*$A21*(1-Assumptions!$E$12)^2*Assumptions!$E$13*Assumptions!$E$14)*(1-Assumptions!$E$17*Assumptions!$E$18)+Model!$E$27-Model!$E$30+Model!$E$54 -> 10235124 | E21: =Model!$E$9*(E$16*12+Model!$E$14*$A21*(1-Assumptions!$E$12)^2*Assumptions!$E$13*Assumptions!$E$14)*(1-Assumptions!$E$17*Assumptions!$E$18)+Model!$E$27-Model!$E$30+Model!$E$54 -> 11027124 | F21: =Model!$E$9*(F$16*12+Model!$E$14*$A21*(1-Assumptions!$E$12)^2*Assumptions!$E$13*Assumptions!$E$14)*(1-Assumptions!$E$17*Assumptions!$E$18)+Model!$E$27-Model!$E$30+Model!$E$54 -> 11819124
A22: 0.08 | B22: =Model!$E$9*(B$16*12+Model!$E$14*$A22*(1-Assumptions!$E$12)^2*Assumptions!$E$13*Assumptions!$E$14)*(1-Assumptions!$E$17*Assumptions!$E$18)+Model!$E$27-Model!$E$30+Model!$E$54 -> 11775445 | C22: =Model!$E$9*(C$16*12+Model!$E$14*$A22*(1-Assumptions!$E$12)^2*Assumptions!$E$13*Assumptions!$E$14)*(1-Assumptions!$E$17*Assumptions!$E$18)+Model!$E$27-Model!$E$30+Model!$E$54 -> 12567445 | D22: =Model!$E$9*(D$16*12+Model!$E$14*$A22*(1-Assumptions!$E$12)^2*Assumptions!$E$13*Assumptions!$E$14)*(1-Assumptions!$E$17*Assumptions!$E$18)+Model!$E$27-Model!$E$30+Model!$E$54 -> 13359445 | E22: =Model!$E$9*(E$16*12+Model!$E$14*$A22*(1-Assumptions!$E$12)^2*Assumptions!$E$13*Assumptions!$E$14)*(1-Assumptions!$E$17*Assumptions!$E$18)+Model!$E$27-Model!$E$30+Model!$E$54 -> 14151445 | F22: =Model!$E$9*(F$16*12+Model!$E$14*$A22*(1-Assumptions!$E$12)^2*Assumptions!$E$13*Assumptions!$E$14)*(1-Assumptions!$E$17*Assumptions!$E$18)+Model!$E$27-Model!$E$30+Model!$E$54 -> 14943445
A23: 0.1 | B23: =Model!$E$9*(B$16*12+Model!$E$14*$A23*(1-Assumptions!$E$12)^2*Assumptions!$E$13*Assumptions!$E$14)*(1-Assumptions!$E$17*Assumptions!$E$18)+Model!$E$27-Model!$E$30+Model!$E$54 -> 14899766 | C23: =Model!$E$9*(C$16*12+Model!$E$14*$A23*(1-Assumptions!$E$12)^2*Assumptions!$E$13*Assumptions!$E$14)*(1-Assumptions!$E$17*Assumptions!$E$18)+Model!$E$27-Model!$E$30+Model!$E$54 -> 15691766 | D23: =Model!$E$9*(D$16*12+Model!$E$14*$A23*(1-Assumptions!$E$12)^2*Assumptions!$E$13*Assumptions!$E$14)*(1-Assumptions!$E$17*Assumptions!$E$18)+Model!$E$27-Model!$E$30+Model!$E$54 -> 16483766 | E23: =Model!$E$9*(E$16*12+Model!$E$14*$A23*(1-Assumptions!$E$12)^2*Assumptions!$E$13*Assumptions!$E$14)*(1-Assumptions!$E$17*Assumptions!$E$18)+Model!$E$27-Model!$E$30+Model!$E$54 -> 17275766 | F23: =Model!$E$9*(F$16*12+Model!$E$14*$A23*(1-Assumptions!$E$12)^2*Assumptions!$E$13*Assumptions!$E$14)*(1-Assumptions!$E$17*Assumptions!$E$18)+Model!$E$27-Model!$E$30+Model!$E$54 -> 18067766
A25: Check: base cell should match Model when inputs equal the selected scenario.

Sheet Sources
A1: Sources & Notes
A3: Fact | B3: Source
A4: NCPA survey (Feb 2026): 67% wait 22+ days for refunds; 78% have reconciliation trouble; 60% dipping into savings | B4: https://www.ncpa.co/pdf/2026/advocacy/mtfsurveyletter.pdf
A5: Plenful (Apr 2026): up to 20% of expected MFP refunds missing at health-system customers | B5: https://www.prnewswire.com/news-releases/plenful-unveils-mfp-command-center-to-help-health-systems-recover-up-to-20-in-missing-medicare-drug-price-refunds-302737691.html
A6: NCPA (Aug 2026): Beacon wrongly classifying claims as 340B (RARC N907) | B6: https://ncpa.org/newsroom/qam/2026/08/27/340b-miscategorization-stealing-your-mfp-refunds
A7: KFF: 2026 (10 drugs), 2027 (15 drugs incl. Ozempic/Wegovy), 2028 (15 incl. Part B) | B7: https://www.kff.org/medicare/key-facts-about-medicare-drug-price-negotiation/
A8: CMS MTF fact sheet: ~21-day average refund timeline; third-party vendor designation | B8: https://www.cms.gov/files/document/pharmacy-dispensing-entity-mtf-fact-sheet.pdf
A9: Beacon MFP FAQ: refund basis = WAC, wholesaler contract price, or 340B price; Resolution Center for disputes | B9: https://mfp.support.beaconchannelmanagement.com/en/articles/12313677-frequently-asked-questions
A10: USC Schaeffer: MFP effectuation data flow and 340B de-duplication challenges | B10: https://schaeffer.usc.edu/research/medicare-drug-prices-mfp-effectuation/
A12: Modeling notes
A13: All volume, pricing, cost and ramp figures are assumptions for planning, not sourced facts. Validate in the pilot.
A14: Ending store counts are net of churn.
A15: Co-op revenue share applies only to pharmacy revenue (subscription + recovery), not Part B clinics.
A16: Part B clinic revenue is a placeholder until CMS finalizes Part B effectuation for 2028.
A17: No refund advances / lending modeled. No taxes, interest, depreciation or outside financing modeled.
